2025-10-04 19:51:18,772 - INFO - Cargadas 34 coordenadas desde caché
2025-10-04 19:51:18,773 - INFO - Cargadas 34 coordenadas desde caché
2025-10-04 19:51:18,776 - INFO - Logging configurado. Archivo: C:\Users\USER\Desktop\backspaceaps\logs\training_20251004_195118.log
2025-10-04 19:51:18,777 - INFO - Cargadas 34 coordenadas desde caché
2025-10-04 19:51:18,780 - INFO - Usando aproximación para código postal 31125 (Chihuahua)
2025-10-04 19:51:18,781 - INFO - GENERANDO PRONOSTICO PARA 31125
2025-10-04 19:51:18,781 - INFO - Usando aproximación para código postal 31125 (Chihuahua)
2025-10-04 19:51:18,782 - INFO - Coordenadas encontradas: 28.632, -106.069
2025-10-04 19:51:18,783 - INFO - Cargando modelo y artefactos...
2025-10-04 19:51:18,784 - INFO - Información del dataset cargada: C:\Users\USER\Desktop\backspaceaps\models\dataset_info.pkl
2025-10-04 19:51:18,913 - INFO - Hiperparámetros cargados: input_size=20, hidden_size=16, model_type=simple
2025-10-04 19:51:22,239 - INFO - Trainer inicializado en dispositivo: cpu
2025-10-04 19:51:22,378 - INFO - Validando hiperparámetros: guardados={'input_size': 20, 'hidden_size': 16, 'num_layers': 1, 'output_steps': 24, 'num_targets': 6, 'model_class': 'WeatherPredictorSimplified'}, actuales={'input_size': 20, 'hidden_size': 16, 'num_layers': 1, 'output_steps': 24, 'num_targets': 6, 'model_class': 'WeatherPredictorSimplified'}
2025-10-04 19:51:22,386 - INFO - Modelo cargado correctamente: C:\Users\USER\Desktop\backspaceaps\models\weather_model.pt
2025-10-04 19:51:22,387 - INFO - Escalador cargado: C:\Users\USER\Desktop\backspaceaps\models\scaler.pkl
2025-10-04 19:51:22,388 - ERROR - Error inesperado cargando modelo: pop from empty list
2025-10-04 19:51:22,396 - ERROR - Traceback (most recent call last):
  File "C:\Users\USER\Desktop\backspaceaps\predict_weather.py", line 118, in load_model
    self.preprocessor.feature_columns = joblib.load(FEATURE_COLUMNS_SAVE_PATH)
                                        ~~~~~~~~~~~^^^^^^^^^^^^^^^^^^^^^^^^^^^
  File "C:\Users\USER\AppData\Roaming\Python\Python313\site-packages\joblib\numpy_pickle.py", line 749, in load
    obj = _unpickle(
        fobj,
    ...<2 lines>...
        mmap_mode=validated_mmap_mode,
    )
  File "C:\Users\USER\AppData\Roaming\Python\Python313\site-packages\joblib\numpy_pickle.py", line 626, in _unpickle
    obj = unpickler.load()
  File "C:\Python313\Lib\pickle.py", line 1256, in load
    dispatch[key[0]](self)
    ~~~~~~~~~~~~~~~~^^^^^^
  File "C:\Python313\Lib\pickle.py", line 1474, in load_tuple
    items = self.pop_mark()
  File "C:\Python313\Lib\pickle.py", line 1263, in pop_mark
    self.stack = self.metastack.pop()
                 ~~~~~~~~~~~~~~~~~~^^
IndexError: pop from empty list

2025-10-04 19:51:22,398 - ERROR - Error en pronostico: No se pudo cargar el modelo de predicción.
